Workbook

Sheet VW+ANDES
A1: Sucursal | B1: Marca | C1: Versión | D1: Código Interno | E1: Año | F1: Numero Chasis | G1: Cliente | H1: Vendedor | I1: Tipo Vehiculo | J1: Forma de Pago | K1: Unidad Costo Factura (-) | L1: Gastos (-) | M1: Trámites (-) | N1: Costo Accesorios (-) | O1: Notas de Crédito (+) | P1: Venta Neta con tramites (+) | Q1: Acción Comercial Contado (Bruto) | R1: Acción Comercial Contado (Neto) (+) | S1: Acción Comercial Crèdito (Bruto) | T1: Acción Comercial Crédito Pagada (Neto) (+) | U1: Bono Crédito (Bruto) | V1: Bono Crédito (Neto) (+) | W1: Bono Volumen Bruto | X1: Bono Volumen Neto (+) | Y1: Margen Final | Z1: Margen con Bonos en Sistema | AA1: Diferencias | AB1: % MARGEN | AC1: Fecha Venta | AD1: Folio Venta | AE1: Rut | AF1: Digito | AG1: Dirección | AH1: Teléfono Fijo | AI1: Teléfono Móvil | AJ1: Teléfono Comercial | AK1: Comuna | AL1: Fecha Nacimiento | AM1: E-mail | AN1: Placa Patente | AO1: Tipo Vehículo | AP1: Modelo | AQ1: Codigo Version | AR1: Color | AS1: Numero VIN | AT1: Numero Serie | AU1: Condición | AV1: Estado Venta | AW1: Folio Facturación | AX1: Fecha Facturación | AY1: Tipo Documento | AZ1: Documento | BA1: Precio Compra | BB1: Vencimiento Factura | BC1: Vendedor Cotización | BD1: Folio | BE1: Medio Contacto | BF1: Vencimiento Documento | BG1: Tipo Venta | BH1: Moneda Venta | BI1: Patente Pago | BJ1: Días Stock | BK1: Precio Lista | BL1: Bono Lista Precio | BM1: Descuento Unidad | BN1: Unidad Venta | BO1: Unidad Costo | BP1: Unidad Margen | BQ1: % | BR1: Tramites Descuento/Recargo | BS1: Tramites Venta | BT1: Tramites Costo | BU1: Tramites Margen | BV1: %1 | BW1: Accesorios Descuento/Recargo | BX1: Accesorios Venta | BY1: Accesorios Costo | BZ1: Accesorios Margen | CA1: %2 | CB1: Contratos DR ML | CC1: Contratos Sub Total ML | CD1: Contratos Costo ML | CE1: Contratos Margen ML | CF1: Contratos Margen Pje | CG1: Total Lista Precio | CH1: SubTotal Venta | CI1: SubTotal Costo | CJ1: SubTotal Margen + Crédito + Seguro | CK1: %3 | CL1: Margen Sin Intereses | CM1: Sub Total Margen ML Sin Inter~s Pje | CN1: Total Interés | CO1: Total Retoma | CP1: Total Abono | CQ1: Total Saldo | CR1: Total Venta Trámite | CS1: Total Venta Accesorios | CT1: Total Venta | CU1: Venta Sin Creditos Y Seguros | CV1: Margen de Venta | CW1: Pje. Margen de Venta | CX1: Entidad Crédito | CY1: Margen Crédito | CZ1: Entidad Seguro | DA1: Margen Seguro | DB1: Bono | DC1: Gasto | DD1: Nacionalidad
A2: CASA MATRIZ NUEVOS | B2: VOLKSWAGEN | C2: Polo 1.6 MT Comfortline - 81 kW/101 CV | D2: AN-25-01-0004 | E2: 2025 | F2: 9BWAL5BZ5ST639230 | G2: ANDREA BETSABE REQUENA ORTIZ | H2: JUAN PABLO GONZALEZ ACUÑA | I2: N | J2: Forum | K2: =BA2 -> 13320731 | L2: 90000 | M2: =BT2 -> 564820 | P2: =CU2 -> 12312719 | Q2: =R2*1.19 -> 1199999.6 | R2: 1008403 | S2: =T2*1.19 -> 999999.84 | T2: 840336 | U2: 150000 | V2: =U2/1.19 -> 126050.42 | W2: =X2*1.19 -> 0 | Y2: =-K2-L2-M2-N2+O2+P2+R2+T2+V2+X2 -> 311957.42 | Z2: =VLOOKUP(D2,'Archivo con Bonos Ingresados '!V:CB,59,0) -> 311957 | AA2: =Z2-Y2 -> -0.42016807 | AB2: =Y2*100/CU2 -> 2.5336193 | AC2: 07-01-2025 11:16:30 | AD2: 5896 | AE2: 17833721 | AF2: 1 | AG2: PASAJE SANTA RAQUEL 0501 | AH2: 976670831 | AK2: PUENTE ALTO | AL2: 19/02/1991 | AM2: requenaortiz@gmail.com | AO2: AUTOMOVIL | AP2: POLO | AQ2: 782024 | AR2: BLANCO CANDY | AS2: 9BWAL5BZ5ST639230 | AT2: 9BWAL5BZ5ST639230 | AU2: NUEVO Y SIN USO | AV2: Facturada | AW2: 19841 | AX2: 09-01-2025 0:00:00 | AZ2: Guía de Despacho: 1 - Factura Electrónica: 1842500 | BA2: 13320731 | BB2: 08-02-2025 0:00:00 | BD2: 0 | BE2: SALON | BF2: 08-02-2025 0:00:00 | BG2: RETAIL | BH2: Peso | BJ2: 0 | BK2: 14277311 | BL2: -2100840 | BM2: -428571 | BN2: 11747899 | BO2: 13320731 | BP2: -1572832 | BQ2: -13.39 % | BR2: 0 | BS2: 564820 | BT2: 564820 | BU2: 0 | BV2: 0 % | BW2: 0 | BX2: 0 | BY2: 0 | BZ2: 0 | CA2: 0 % | CB2: 0 | CC2: 0 | CD2: 0 | CE2: 0 | CF2: 0 % | CG2: 12176471 | CH2: 12312719 | CI2: 13885551 | CJ2: -1572832 | CK2: -12.77 % | CL2: -1572832 | CM2: -12.77 % | CN2: 0 | CO2: 0 | CP2: 14544820 | CQ2: 0 | CR2: 564820 | CS2: 0 | CT2: 14544820 | CU2: 12312719 | CV2: -1572832 | CW2: -12.77 % | CY2: 0 | DA2: 0 | DB2: 0 | DC2: 0
A3: ANDES MOTOR | B3: MAXUS | C3: T60 4X2 GL MT E6 | D3: AN-24-08-0083 | E3: 2025 | F3: LSFAM11A4RA077914 | G3: ASCANIO OSORIO AVENDAÑO SER.ING.MEC.MOT.ASES.PINT.IND.Y GRALES .EIRL | H3: Manuel Rodrigo Hurtado Melo | I3: N | J3: Directo | K3: =BA3 -> 19586800 | L3: 235000 | M3: =BT3 -> 658602 | P3: =CU3 -> 19130902 | Q3: =R3*1.19 -> 2026808 | R3: 1703200 | S3: =T3*1.19 -> 0 | V3: =U3/1.19 -> 0 | W3: =X3*1.19 -> 0 | Y3: =-K3-L3-M3-N3+O3+P3+R3+T3+V3+X3 -> 353700 | Z3: =VLOOKUP(D3,'Archivo con Bonos Ingresados '!V:CB,59,0) -> 353700 | AA3: =Z3-Y3 -> 0 | AB3: =Y3*100/CU3 -> 1.8488412 | AC3: 10-01-2025 15:37:20 | AD3: 5911 | AE3: 76692680 | AF3: 0 | AG3: PETRONILA 149 50 | AI3: 985433201 | AK3: ANTOFAGASTA | AL3: 01/01/2022 | AM3: ascanio.osorioc@gmail.com | AP3: T60 | AQ3: T60 4X2 GL MT E6 | AR3: GRIS | AS3: LSFAM11A4RA077914 | AT3: LSFAM11A4RA077914 | AU3: NUEVO Y SIN USO | AV3: Parcial Facturada | AW3: 19862 | AX3: 14-01-2025 0:00:00 | AZ3: Guía de Despacho: 1 - Factura Electrónica: 186708 | BA3: 19586800 | BB3: 14-01-2025 0:00:00 | BD3: 0 | BE3: SITIO WEB | BF3: 14-01-2025 0:00:00 | BG3: FLOTA | BH3: Peso | BJ3: 109 | BK3: 21290000 | BL3: -2767700 | BM3: -50000 | BN3: 18472300 | BO3: 19586800 | BP3: -1114500 | BQ3: -6.03 % | BR3: 0 | BS3: 658602 | BT3: 658602 | BU3: 0 | BV3: 0 % | BW3: 0 | BX3: 0 | BY3: 0 | BZ3: 0 | CA3: 0 % | CB3: 0 | CC3: 0 | CD3: 0 | CE3: 0 | CF3: 0 % | CG3: 18522300 | CH3: 19130902 | CI3: 20245402 | CJ3: -1114500 | CK3: -5.83 % | CL3: -1114500 | CM3: -5.83 % | CN3: 0 | CO3: 0 | CP3: 22640639 | CQ3: 0 | CR3: 658602 | CS3: 0 | CT3: 22640639 | CU3: 19130902 | CV3: -1114500 | CW3: -5.83 % | CY3: 0 | DA3: 0 | DB3: 0 | DC3: 0
A4: CASA MATRIZ NUEVOS | B4: VOLKSWAGEN | C4: T-Cross 1.0 TSI AT Highline - 85 kW/116 CV | D4: AN-24-12-0036 | E4: 2025 | F4: 9BWBH6BF2S4053564 | G4: BERNARDITA MARIA SOLER LEON | H4: ROBERTO LOBOS GUTIERREZ | I4: N | J4: Directo | K4: =BA4 -> 17651815 | L4: 175000 | M4: =BT4 -> 977613 | P4: =CU4 -> 18338958 | Q4: =R4*1.19 -> 1449999.5 | R4: 1218487 | S4: =T4*1.19 -> 0 | V4: =U4/1.19 -> 0 | W4: =X4*1.19 -> 224900.48 | X4: 188992 | Y4: =-K4-L4-M4-N4+O4+P4+R4+T4+V4+X4 -> 942009 | Z4: =VLOOKUP(D4,'Archivo con Bonos Ingresados '!V:CB,59,0) -> 942009 | AA4: =Z4-Y4 -> 0 | AB4: =Y4*100/CU4 -> 5.136655 | AC4: 24-01-2025 17:04:54 | AD4: 5958 | AE4: 15313830 | AF4: 3 | AG4: VASCO DE GAMA 4596 DEPTO 17 | AI4: 961689307 | AK4: LAS CONDES | AL4: 01/01/1900 | AM4: bernarditasoler@gmail.com | AO4: STATION WAGON | AP4: T CROSS | AQ4: BF34K311 | AR4: PLATA PIRITA | AS4: 9BWBH6BF2S4053564 | AT4: 9BWBH6BF2S4053564 | AU4: NUEVO Y SIN USO | AV4: Parcial Facturada | AW4: 19918 | AX4: 27-01-2025 0:00:00 | AZ4: Guía de Despacho: 1 - Factura Electrónica: 1841782 | BA4: 17651815 | BB4: 27-01-2025 0:00:00 | BD4: 0 | BE4: WEB CONCESIONARIO | BF4: 27-01-2025 0:00:00 | BG4: CC | BH4: Peso | BJ4: 39 | BK4: 18899160 | BL4: -1218487 | BM4: -571429 | BN4: 17109244 | BO4: 17651815 | BP4: -542571 | BQ4: -3.17 % | BR4: 0 | BS4: 977613 | BT4: 977613 | BU4: 0 | BV4: 0 % | BW4: 55336 | BX4: 252101 | BY4: 0 | BZ4: 0 | CA4: 0 % | CB4: 0 | CC4: 0 | CD4: 0 | CE4: 0 | CF4: 0 % | CG4: 17680673 | CH4: 18338958 | CI4: 18629428 | CJ4: -290470 | CK4: -1.58 % | CL4: -290470 | CM4: -1.58 % | CN4: 0 | CO4: 0 | CP4: 21637613 | CQ4: 0 | CR4: 977613 | CS4: 252101 | CT4: 21637614 | CU4: 18338958 | CV4: -290470 | CW4: -1.58 % | CY4: 0 | DA4: 0 | DB4: 0 | DC4: 0
A5: CASA MATRIZ NUEVOS | B5: VOLKSWAGEN | C5: Saveiro 1.6 MT Cabina Simple Lite | D5: AN-24-11-0061 | E5: 2025 | F5: 9BWKL45UXSP031761 | G5: COMERCIAL OXIPROTEX LTDA. | H5: ROBERTO LOBOS GUTIERREZ | I5: N | J5: Directo | K5: =BA5 -> 11047360 | L5: 90000 | M5: =BT5 -> 0 | P5: =CU5 -> 11344538 | Q5: =R5*1.19 -> 1487500 | R5: 1250000 | S5: =T5*1.19 -> 0 | V5: =U5/1.19 -> 0 | W5: =X5*1.19 -> 0 | Y5: =-K5-L5-M5-N5+O5+P5+R5+T5+V5+X5 -> 1457178 | Z5: =VLOOKUP(D5,'Archivo con Bonos Ingresados '!V:CB,59,0) -> 1457178 | AA5: =Z5-Y5 -> 0 | AB5: =Y5*100/CU5 -> 12.844754 | AC5: 14-01-2025 14:19:05 | AD5: 5926 | AE5: 76937697 | AF5: 6 | AG5: FCO. BILBAO 1860 3 301 | AH5: 64 2644300 | AK5: OSORNO | AL5: 01/01/2000 | AM5: ABASTECIMIENTO@INTEGRA-CHILE.CL | AO5: CAMIONETA | AP5: SAVEIRO | AQ5: 5URTT412 | AR5: BLANCO CANDY | AS5: 9BWKL45UXSP031761 | AT5: 9BWKL45UXSP031761 | AU5: NUEVO Y SIN USO | AV5: Facturada | AW5: 19936 | AX5: 29-01-2025 0:00:00 | AZ5: Guía de Despacho: 1 - Factura Electrónica: 1840823 - Nota de Crédito Electrónica: 3062529 | BA5: 11047360 | BB5: 28-02-2025 0:00:00 | BD5: 0 | BE5: SALON | BF5: 28-02-2025 0:00:00 | BG5: CC | BH5: Peso | BJ5: 0 | BK5: 12640000 | BL5: -1295462 | BM5: 0 | BN5: 11344538 | BO5: 9797360 | BP5: 1547178 | BQ5: 13.64 % | BR5: 0 | BS5: 0 | BT5: 0 | BU5: 0 | BV5: 0 % | BW5: 0 | BX5: 0 | BY5: 0 | BZ5: 0 | CA5: 0 % | CB5: 0 | CC5: 0 | CD5: 0 | CE5: 0 | CF5: 0 % | CG5: 11344538 | CH5: 11344538 | CI5: 9797360 | CJ5: 1547178 | CK5: 13.64 % | CL5: 1547178 | CM5: 13.64 % | CN5: 0 | CO5: 0 | CP5: 13500000 | CQ5: 0 | CR5: 0 | CS5: 0 | CT5: 13500000 | CU5: 11344538 | CV5: 1547178 | CW5: 13.64 % | CY5: 0 | DA5: 0 | DB5: 1487500 | DC5: 0
A6: CASA MATRIZ NUEVOS | B6: VOLKSWAGEN | C6: Saveiro 1.6 MT Cabina Simple Lite | D6: AN-24-11-0062 | E6: 2025 | F6: 9BWKL45UXSP033087 | G6: CONSULTORA Y GESTION DEXTRA LIMITADA | H6: JUAN PABLO GONZALEZ ACUÑA | I6: N | J6: Forum | K6: =BA6 -> 11047360 | L6: 90000 | M6: =BT6 -> 299330 | P6: =CU6 -> 10075330 | Q6: =R6*1.19 -> 1487500 | R6: 1250000 | S6: =T6*1.19 -> 0 | U6: 150000 | V6: =U6/1.19 -> 126050.42 | W6: =X6*1.19 -> 499999.92 | X6: 420168 | Y6: =-K6-L6-M6-N6+O6+P6+R6+T6+V6+X6 -> 434858.42 | Z6: =VLOOKUP(D6,'Archivo con Bonos Ingresados '!V:CB,59,0) -> 14690 | AA6: =Z6-Y6 -> -420168.42 | AB6: =Y6*100/CU6 -> 4.3160712 | AC6: 08-01-2025 11:12:40 | AD6: 5898 | AE6: 76193982 | AF6: 3 | AG6: BADAJOZ 100 OF 1003 PISO 10 | AH6: 977092999 | AK6: LAS CONDES | AM6: roberto.alvarez@dextraltda.cl | AO6: CAMIONETA | AP6: SAVEIRO | AQ6: 5URTT412 | AR6: BLANCO CANDY | AS6: 9BWKL45UXSP033087 | AT6: 9BWKL45UXSP033087 | AU6: NUEVO Y SIN USO | AV6: Facturada | AW6: 19852 | AX6: 13-01-2025 0:00:00 | AZ6: Guía de Despacho: 1 - Factura Electrónica: 1840743 - Nota de Crédito Electrónica: 3062485 | BA6: 11047360 | BB6: 12-02-2025 0:00:00 | BD6: 0 | BE6: SALON | BF6: 12-02-2025 0:00:00 | BG6: RETAIL | BH6: Peso | BJ6: 0 | BK6: 12640000 | BL6: -2050000 | BM6: -814000 | BN6: 9776000 | BO6: 9797360 | BP6: -21360 | BQ6: -0.22 % | BR6: 0 | BS6: 299330 | BT6: 299330 | BU6: 0 | BV6: 0 % | BW6: 0 | BX6: 0 | BY6: 0 | BZ6: 0 | CA6: 0 % | CB6: 0 | CC6: 0 | CD6: 0 | CE6: 0 | CF6: 0 % | CG6: 10590000 | CH6: 10075330 | CI6: 10096690 | CJ6: -21360 | CK6: -0.21 % | CL6: -21360 | CM6: -0.21 % | CN6: 0 | CO6: 0 | CP6: 11932770 | CQ6: 0 | CR6: 299330 | CS6: 0 | CT6: 11932770 | CU6: 10075330 | CV6: -21360 | CW6: -0.21 % | CY6: 0 | DA6: 0 | DB6: 1487500 | DC6: 0
A7: CASA MATRIZ NUEVOS | B7: VOLKSWAGEN | C7: Saveiro 1.6 MT Cabina Simple Lite | D7: AN-24-11-0082 | E7: 2025 | F7: 9BWKL45UXSP007119 | G7: DANDILION INSPECCION LIMITADA | H7: JUAN PABLO GONZALEZ ACUÑA | I7: N | J7: Santander | K7: =BA7 -> 11047360 | L7: 90000 | M7: =BT7 -> 381560 | P7: =CU7 -> 10157560 | Q7: =R7*1.19 -> 1687499.7 | R7: 1418067 | S7: =T7*1.19 -> 0 | V7: =U7/1.19 -> 0 | W7: =X7*1.19 -> 499999.92 | X7: 420168 | Y7: =-K7-L7-M7-N7+O7+P7+R7+T7+V7+X7 -> 476875 | Z7: =VLOOKUP(D7,'Archivo con Bonos Ingresados '!V:CB,59,0) -> 56707 | AA7: =Z7-Y7 -> -420168 | AB7: =Y7*100/CU7 -> 4.6947791 | AC7: 07-01-2025 10:13:45 | AD7: 5894 | AE7: 76296875 | AF7: 4 | AG7: LAREDO 8357 OF 21 | AH7: 954061070 | AK7: LAS CONDES | AM7: eruz@dandilion.cl | AO7: CAMIONETA | AP7: SAVEIRO | AQ7: 5URTT412 | AR7: BLANCO CANDY | AS7: 9BWKL45UXSP007119 | AT7: 9BWKL45UXSP007119 | AU7: NUEVO Y SIN USO | AV7: Facturada | AW7: 19857 | AX7: 14-01-2025 0:00:00 | AZ7: Guía de Despacho: 1 - Factura Electrónica: 1840728 - Nota de Crédito Electrónica: 3062075 | BA7: 11047360 | BB7: 14-01-2025 0:00:00 | BD7: 0 | BE7: SALON | BF7: 14-01-2025 0:00:00 | BG7: RETAIL | BH7: Peso | BJ7: 0 | BK7: 12640000 | BL7: -2050000 | BM7: -814000 | BN7: 9776000 | BO7: 9629293 | BP7: 146707 | BQ7: 1.5 % | BR7: 0 | BS7: 381560 | BT7: 381560 | BU7: 0 | BV7: 0 % | BW7: 0 | BX7: 0 | BY7: 0 | BZ7: 0 | CA7: 0 % | CB7: 0 | CC7: 0 | CD7: 0 | CE7: 0 | CF7: 0 % | CG7: 10590000 | CH7: 10157560 | CI7: 10010853 | CJ7: 146707 | CK7: 1.44 % | CL7: 146707 | CM7: 1.44 % | CN7: 0 | CO7: 0 | CP7: 12015000 | CQ7: 0 | CR7: 381560 | CS7: 0 | CT7: 12015000 | CU7: 10157560 | CV7: 146707 | CW7: 1.44 % | CY7: 0 | DA7: 0 | DB7: 1687500 | DC7: 0
A8: CASA MATRIZ NUEVOS | B8: VOLKSWAGEN | C8: Saveiro 1.6 MT Cabina Simple Lite | D8: AN-24-11-0060 | E8: 2025 | F8: 9BWKL45U9SP015874 | G8: DANDILION INSPECCION LIMITADA | H8: JUAN PABLO GONZALEZ ACUÑA | I8: N | J8: Santander | K8: =BA8 -> 11047360 | L8: 90000 | M8: =BT8 -> 381560 | P8: =CU8 -> 10971560 | Q8: =R8*1.19 -> 1687499.7 | R8: 1418067 | S8: =T8*1.19 -> 0 | V8: =U8/1.19 -> 0 | W8: =X8*1.19 -> 0 | Y8: =-K8-L8-M8-N8+O8+P8+R8+T8+V8+X8 -> 870707 | Z8: =VLOOKUP(D8,'Archivo con Bonos Ingresados '!V:CB,59,0) -> 870707 | AA8: =Z8-Y8 -> 0 | AB8: =Y8*100/CU8 -> 7.9360364 | AC8: 07-01-2025 10:15:54 | AD8: 5895 | AE8: 76296875 | AF8: 4 | AG8: LAREDO 8357 OF 21 | AH8: 954061070 | AK8: LAS CONDES | AM8: eruz@dandilion.cl | AO8: CAMIONETA | AP8: SAVEIRO | AQ8: 5URTT412 | AR8: BLANCO CANDY | AS8: 9BWKL45U9SP015874 | AT8: 9BWKL45U9SP015874 | AU8: NUEVO Y SIN USO | AV8: Facturada | AW8: 19858 | AX8: 14-01-2025 0:00:00 | AZ8: Guía de Despacho: 1 - Factura Electrónica: 1840658 - Nota de Crédito Electrónica: 3062073 | BA8: 11047360 | BB8: 14-01-2025 0:00:00 | BD8: 0 | BE8: SALON | BF8: 14-01-2025 0:00:00 | BG8: FLOTA | BH8: Peso | BJ8: 0 | BK8: 12640000 | BL8: -2050000 | BM8: 0 | BN8: 10590000 | BO8: 9629293 | BP8: 960707 | BQ8: 9.07 % | BR8: 0 | BS8: 381560 | BT8: 381560 | BU8: 0 | BV8: 0 % | BW8: 0 | BX8: 0 | BY8: 0 | BZ8: 0 | CA8: 0 % | CB8: 0 | CC8: 0 | CD8: 0 | CE8: 0 | CF8: 0 % | CG8: 10590000 | CH8: 10971560 | CI8: 10010853 | CJ8: 960707 | CK8: 8.76 % | CL8: 960707 | CM8: 8.76 % | CN8: 0 | CO8: 0 | CP8: 14657464 | CQ8: -1673804 | CR8: 381560 | CS8: 0 | CT8: 12983660 | CU8: 10971560 | CV8: 960707 | CW8: 8.76 % | CY8: 0 | DA8: 0 | DB8: 1687500 | DC8: 0
A9: CASA MATRIZ NUEVOS | B9: VOLKSWAGEN | C9: Nivus 1.0 TSI AT Highline 85KW/116CV 5 p | D9: AN-25-01-0035 | E9: 2025 | F9: 9BWCH6CH8RP052805 | G9: DANIEL JACK BROOKS BRAVO | H9: ROBERTO LOBOS GUTIERREZ | I9: N | J9: Lucy | K9: =BA9 -> 18103335 | L9: 145000 | M9: =BT9 -> 784164 | P9: =CU9 -> 15910214 | Q9: =R9*1.19 -> 3150000.2 | R9: 2647059 | S9: =T9*1.19 -> 999999.84 | T9: 840336 | U9: 150000 | V9: =U9/1.19 -> 126050.42 | W9: =X9*1.19 -> 230900.46 | X9: 194034 | Y9: =-K9-L9-M9-N9+O9+P9+R9+T9+V9+X9 -> 685194.42 | Z9: =VLOOKUP(D9,'Archivo con Bonos Ingresados '!V:CB,59,0) -> 685194 | AA9: =Z9-Y9 -> -0.42016807 | AB9: =Y9*100/CU9 -> 4.3066323 | AC9: 23-01-2025 16:36:11 | AD9: 5954 | AE9: 19894192 | AF9: 1 | AG9: MONROE 6584 | AI9: 969160087 | AK9: LAS CONDES | AL9: 01/01/1900 | AM9: Djbrookssb@gmail.com | AO9: STATION WAGON | AP9: FAMILIA 1 | AQ9: CH14K311 | AR9: Gris Piedra de Luna | AS9: 9BWCH6CH8RP052805 | AT9: 9BWCH6CH8RP052805 | AU9: NUEVO Y SIN USO | AV9: Facturada | AW9: 19920 | AX9: 27-01-2025 0:00:00 | AZ9: Guía de Despacho: 1 - Factura Electrónica: 1864596 | BA9: 18103335 | BB9: 26-02-2025 0:00:00 | BD9: 0 | BE9: WEB CONCESIONARIO | BF9: 26-02-2025 0:00:00 | BG9: CI | BH9: Peso | BJ9: 0 | BK9: 19403361 | BL9: -3739496 | BM9: -537815 | BN9: 15126050 | BO9: 18103335 | BP9: -2977285 | BQ9: -19.68 % | BR9: 0 | BS9: 784164 | BT9: 784164 | BU9: 0 | BV9: 0 % | BW9: 0 | BX9: 0 | BY9: 0 | BZ9: 0 | CA9: 0 % | CB9: 0 | CC9: 0 | CD9: 0 | CE9: 0 | CF9: 0 % | CG9: 15663865 | CH9: 15910214 | CI9: 18887499 | CJ9: -2977285 | CK9: -18.71 % | CL9: -2977285 | CM9: -18.71 % | CN9: 0 | CO9: 0 | CP9: 18784164 | CQ9: 0 | CR9: 784164 | CS9: 0 | CT9: 18784164 | CU9: 15910214 | CV9: -2977285 | CW9: -18.71 % | CY9: 0 | DA9: 0 | DB9: 0 | DC9: 0
A10: ANDES MOTOR | B10: KAIYI | C10: KYE5 1.5T MT LUX | D10: AN-24-03-0009 | E10: 2025 | F10: LUYJA1G22RA003056 | G10: DIEGO ALEJANDRO JIMENEZ SILVA | H10: Marcos Ignacio Campos Zavala | I10: N | J10: Tanner | K10: =BA10 -> 11588907 | L10: 90000 | M10: =BT10 -> 669467 | P10: =CU10 -> 10987450 | Q10: 1200000 | R10: =Q10/1.19 -> 1008403.4 | S10: =T10*1.19 -> 0 | U10: 1000000 | V10: =U10/1.19 -> 840336.13 | W10: =X10*1.19 -> 0 | Y10: =-K10-L10-M10-N10+O10+P10+R10+T10+V10+X10 -> 487815.5 | Z10: =VLOOKUP(D10,'Archivo con Bonos Ingresados '!V:CB,59,0) -> 487815 | AA10: =Z10-Y10 -> -0.49579832 | AB10: =Y10*100/CU10 -> 4.4397517 | AC10: 11-01-2025 12:06:24 | AD10: 5915 | AE10: 16802706 | AF10: 0 | AG10: EJERCITO LIBERTADOR 2120 CASA 297 | AI10: 985658267 | AK10: PUENTE ALTO | AL10: 22/09/1987 | AM10: COMERCIALA07SPA@GMAIL.COM | AP10: KYE5 | AQ10: KYE5 1.5T MT LUX | AR10: GRIS | AS10: LUYJA1G22RA003056 | AT10: LUYJA1G22RA003056 | AU10: NUEVO Y SIN USO | AV10: Parcial Facturada | AW10: 19872 | AX10: 15-01-2025 0:00:00 | AZ10: Guía de Despacho Electrónica: 1 - Factura Electrónica: 168809 | BA10: 11588907 | BB10: 14-02-2025 0:00:00 | BD10: 0 | BE10: WEB CONCESIONARIO | BF10: 14-02-2025 0:00:00 | BG10: RETAIL | BH10: Peso | BJ10: 0 | BK10: 12596639 | BL10: -1848739 | BM10: -429916 | BN10: 10317983 | BO10: 11588907 | BP10: -1270924 | BQ10: -12.32 % | BR10: 0 | BS10: 669467 | BT10: 669467 | BU10: 0 | BV10: 0 % | BW10: 0 | BX10: 0 | BY10: 0 | BZ10: 0 | CA10: 0 % | CB10: 0 | CC10: 0 | CD10: 0 | CE10: 0 | CF10: 0 % | CG10: 10747900 | CH10: 10987450 | CI10: 12258374 | CJ10: -1270924 | CK10: -11.57 % | CL10: -1270924 | CM10: -11.57 % | CN10: 0 | CO10: 0 | CP10: 12947867 | CQ10: 0 | CR10: 669467 | CS10: 0 | CT10: 12947867 | CU10: 10987450 | CV10: -1270924 | CW10: -11.57 % | CY10: 0 | DA10: 0 | DB10: 0 | DC10: 0
A11: CASA MATRIZ NUEVOS | B11: VOLKSWAGEN | C11: T-Cross 1.0 TSI AT Highline - 85 kW/116 CV | D11: AN-24-12-0032 | E11: 2025 | F11: 9BWBH6BF0S4053238 | G11: DOBRA WALESKA LUSIC MORALES | H11: JUAN PABLO GONZALEZ ACUÑA | I11: N | J11: Directo | K11: =BA11 -> 17651815 | L11: 175000 | M11: =BT11 -> 973956 | P11: =CU11 -> 17898326 | Q11: =R11*1.19 -> 1449999.5 | R11: 1218487 | S11: =T11*1.19 -> 0 | V11: =U11/1.19 -> 0 | W11: =X11*1.19 -> 224900.48 | X11: 188992 | Y11: =-K11-L11-M11-N11+O11+P11+R11+T11+V11+X11 -> 505034 | Z11: =VLOOKUP(D11,'Archivo con Bonos Ingresados '!V:CB,59,0) -> 505034 | AA11: =Z11-Y11 -> 0 | AB11: =Y11*100/CU11 -> 2.8216829 | AC11: 09-01-2025 15:45:12 | AD11: 5905 | AE11: 16748913 | AF11: 3 | AG11: GENERAL JOFRE 202 DPTO 507 | AH11: 957148023 | AK11: SANTIAGO | AL11: 02/03/1988 | AM11: dobralusic@gmail.com | AO11: STATION WAGON | AP11: T CROSS | AQ11: BF34K311 | AR11: BLANCO PURO | AS11: 9BWBH6BF0S4053238 | AT11: 9BWBH6BF0S4053238 | AU11: NUEVO Y SIN USO | AV11: Facturada | AW11: 19859 | AX11: 14-01-2025 0:00:00 | AZ11: Guía de Despacho: 1 - Factura Electrónica: 1841780 | BA11: 17651815 | BB11: 14-01-2025 0:00:00 | BD11: 0 | BE11: SALON | BF11: 14-01-2025 0:00:00 | BG11: RETAIL | BH11: Peso | BJ11: 26 | BK11: 18899160 | BL11: -1218487 | BM11: -756303 | BN11: 16924370 | BO11: 17651815 | BP11: -727445 | BQ11: -4.3 % | BR11: 0 | BS11: 973956 | BT11: 973956 | BU11: 0 | BV11: 0 % | BW11: 0 | BX11: 0 | BY11: 0 | BZ11: 0 | CA11: 0 % | CB11: 0 | CC11: 0 | CD11: 0 | CE11: 0 | CF11: 0 % | CG11: 17680673 | CH11: 17898326 | CI11: 18625771 | CJ11: -727445 | CK11: -4.06 % | CL11: -727445 | CM11: -4.06 % | CN11: 0 | CO11: 0 | CP11: 21113956 | CQ11: 0 | CR11: 973956 | CS11: 0 | CT11: 21113956 | CU11: 17898326 | CV11: -727445 | CW11: -4.06 % | CY11: 0 | DA11: 0 | DB11: 0 | DC11: 0
A12: ANDES MOTOR | B12: MAXUS | C12: D60 4X2 LUX AT 7P | D12: AN-24-09-0044 | E12: 2025 | F12: LSKG4BC13SD040453 | G12: ENNIO MAURICIO GRBAC NUÑEZ | H12: SERGIO POBLETE CAMPOS | I12: N | J12: BK | K12: =BA12 -> 17773781 | L12: 235000 | M12: =BT12 -> 1000000 | P12: =CU12 -> 17798319 | Q12: =R12*1.19 -> 1000000 | R12: 840336.13 | S12: =T12*1.19 -> 0 | U12: =V12*1.19 -> 800000.11 | V12: =126050+546219 -> 672269 | W12: =X12*1.19 -> 0 | Y12: =-K12-L12-M12-N12+O12+P12+R12+T12+V12+X12 -> 302143.13 | Z12: =VLOOKUP(D12,'Archivo con Bonos Ingresados '!V:CB,59,0) -> 302143 | AA12: =Z12-Y12 -> -0.13445378 | AB12: =Y12*100/CU12 -> 1.6975937 | AC12: 21-01-2025 11:03:39 | AD12: 5943 | AE12: 7131041 | AF12: 8 | AG12: TONGOY 1157 | AH12: 67275763 | AI12: +569 67275763 | AK12: LAS CONDES | AL12: 20/12/1964 | AM12: enniogrbac@grbac.cl | AP12: D60 | AQ12: D60 4X2 LUX AT 7P | AR12: PLATA | AS12: LSKG4BC13SD040453 | AT12: LSKG4BC13SD040453 | AU12: NUEVO Y SIN USO | AV12: Parcial Facturada | AW12: 19907 | AX12: 23-01-2025 0:00:00 | AZ12: Guía de Despacho: 1 - Factura Electrónica: 205322 | BA12: 17773781 | BB12: 22-02-2025 0:00:00 | BD12: 0 | BE12: SALON | BF12: 22-02-2025 0:00:00 | BG12: CC | BH12: Peso | BI12: KBBL13 | BJ12: 115 | BK12: 19319328 | BL12: -1680672 | BM12: -840336 | BN12: 16798319 | BO12: 17773781 | BP12: -975462 | BQ12: -5.81 % | BR12: 0 | BS12: 1000000 | BT12: 1000000 | BU12: 0 | BV12: 0 % | BW12: 0 | BX12: 0 | BY12: 0 | BZ12: 0 | CA12: 0 % | CB12: 0 | CC12: 0 | CD12: 0 | CE12: 0 | CF12: 0 % | CG12: 17638656 | CH12: 17798319 | CI12: 18773781 | CJ12: -975462 | CK12: -5.48 % | CL12: -975462 | CM12: -5.48 % | CN12: 0 | CO12: 6300000 | CP12: 14690000 | CQ12: 0 | CR12: 1000000 | CS12: 0 | CT12: 20990000 | CU12: 17798319 | CV12: -975462 | CW12: -5.48 % | CY12: 0 | DA12: 0 | DB12: 0 | DC12: 0
A13: CASA MATRIZ NUEVOS | B13: VOLKSWAGEN | C13: NUEVO TIGUAN TSI AT COMFORTLINE 150HP | D13: AN-25-01-0008 | E13: 2025 | F13: 3VVHP65N7RM219894 | G13: ENRIQUE EDUARDO LATOJA OVIEDO | H13: JUAN PABLO GONZALEZ ACUÑA | I13: N | J13: Directo | K13: =BA13 -> 23804093 | L13: 175000 | M13: =BT13 -> 1581111 | P13: =CU13 -> 24160355 | Q13: =R13*1.19 -> 2900000.2 | R13: 2436975 | S13: =T13*1.19 -> 0 | V13: =U13/1.19 -> 0 | W13: =X13*1.19 -> 306899.81 | X13: 257899 | Y13: =-K13-L13-M13-N13+O13+P13+R13+T13+V13+X13 -> 1295025 | Z13: =VLOOKUP(D13,'Archivo con Bonos Ingresados '!V:CB,59,0) -> 1295025 | AA13: =Z13-Y13 -> 0 | AB13: =Y13*100/CU13 -> 5.3601241 | AC13: 13-01-2025 10:23:49 | AD13: 5917 | AE13: 7918183 | AF13: 8 | AG13: JANUARIO ESPINOZA 7205-A | AH13: 998213308 | AK13: LA REINA | AL13: 11/06/1959 | AM13: elatoja@entel.cl | AO13: STATION WAGON 01 | AP13: FAMILIA 1 | AQ13: BJ23N611 | AR13: PLATA PIRITA | AS13: 3VVHP65N7RM219894 | AU13: NUEVO Y SIN USO | AV13: Facturada | AW13: 19861 | AX13: 14-01-2025 0:00:00 | AZ13: Guía de Despacho: 1 - Factura Electrónica: 1864398 | BA13: 23804093 | BB13: 14-01-2025 0:00:00 | BD13: 0 | BE13: SALON | BF13: 14-01-2025 0:00:00 | BG13: RETAIL | BH13: Peso | BJ13: 0 | BK13: 25789916 | BL13: -2436975 | BM13: -773697 | BN13: 22579244 | BO13: 23804093 | BP13: -1224849 | BQ13: -5.42 % | BR13: 0 | BS13: 1581111 | BT13: 1581111 | BU13: 0 | BV13: 0 % | BW13: 0 | BX13: 0 | BY13: 0 | BZ13: 0 | CA13: 0 % | CB13: 0 | CC13: 0 | CD13: 0 | CE13: 0 | CF13: 0 % | CG13: 23352941 | CH13: 24160355 | CI13: 25385204 | CJ13: -1224849 | CK13: -5.07 % | CL13: -1224849 | CM13: -5.07 % | CN13: 0 | CO13: 0 | CP13: 28450411 | CQ13: 0 | CR13: 1581111 | CS13: 0 | CT13: 28450411 | CU13: 24160355 | CV13: -1224849 | CW13: -5.07 % | CY13: 0 | DA13: 0 | DB13: 0 | DC13: 0
A14: CASA MATRIZ NUEVOS | B14: VOLKSWAGEN | C14: T-Cross 1.0 TSI MT Comfortline - 74 kW/101 CV | D14: AN-24-08-0072 | E14: 2025 | F14: 9BWBH6BF7S4004618 | G14: FRANCESCA MARIA DE LOURDES CALVANESE HUIDOBRO | H14: JUAN PABLO GONZALEZ ACUÑA | I14: N | J14: Directo | K14: =BA14 -> 15795707 | L14: 175000 | M14: =BT14 -> 860724 | P14: =CU14 -> 15763497 | Q14: =R14*1.19 -> 1850000.2 | R14: 1554622 | S14: =T14*1.19 -> 0 | V14: =U14/1.19 -> 0 | W14: =X14*1.19 -> 201900.16 | X14: 169664 | Y14: =-K14-L14-M14-N14+O14+P14+R14+T14+V14+X14 -> 656352 | Z14: =VLOOKUP(D14,'Archivo con Bonos Ingresados '!V:CB,59,0) -> 656352 | AA14: =Z14-Y14 -> 0 | AB14: =Y14*100/CU14 -> 4.1637462 | AC14: 27-01-2025 18:15:38 | AD14: 5960 | AE14: 8545815 | AF14: 9 | AG14: HERNANDO DE MAGALLANES 1922 | AH14: 996897113 | AK14: LAS CONDES | AL14: 06/06/1959 | AM14: francescacalvanese@gmail.com | AO14: STATION WAGON | AP14: T CROSS | AQ14: BF33D411 | AR14: AZUL NORUEGA | AS14: 9BWBH6BF7S4004618 | AT14: 9BWBH6BF7S4004618 | AU14: NUEVO Y SIN USO | AV14: Facturada | AW14: 19926 | AX14: 28-01-2025 0:00:00 | AZ14: Guía de Despacho: 1 - Factura Electrónica: 1838082 | BA14: 15795707 | BB14: 28-01-2025 0:00:00 | BD14: 0 | BE14: SALON | BF14: 28-01-2025 0:00:00 | BG14: RETAIL | BH14: Peso | BJ14: 123 | BK14: 16966386 | BL14: -1554622 | BM14: -508992 | BN14: 14902773 | BO14: 15795707 | BP14: -892934 | BQ14: -5.99 % | BR14: 0 | BS14: 860724 | BT14: 860724 | BU14: 0 | BV14: 0 % | BW14: 0 | BX14: 0 | BY14: 0 | BZ14: 0 | CA14: 0 % | CB14: 0 | CC14: 0 | CD14: 0 | CE14: 0 | CF14: 0 % | CG14: 15411764 | CH14: 15763497 | CI14: 16656431 | CJ14: -892934 | CK14: -5.66 % | CL14: -892934 | CM14: -5.66 % | CN14: 0 | CO14: 0 | CP14: 18595024 | CQ14: 0 | CR14: 860724 | CS14: 0 | CT14: 18595024 | CU14: 15763497 | CV14: -892934 | CW14: -5.66 % | CY14: 0 | DA14: 0 | DB14: 0 | DC14: 0
A15: CASA MATRIZ NUEVOS | B15: VOLKSWAGEN | C15: NUEVO ATLAS 2.0 TSI AT LIMITED 4MOTION | D15: AN-24-12-0042 | E15: 2025 | F15: WVGZZZCA5RC601451 | G15: FRANCISCA ANDREA RIQUELME FENNER | H15: ROBERTO LOBOS GUTIERREZ | I15: N | J15: Directo | K15: =BA15 -> 43474588 | L15: 235000 | M15: =BT15 -> 2749605 | P15: =CU15 -> 44926495 | Q15: =R15*1.19 -> 2999999.5 | R15: 2521008 | S15: =T15*1.19 -> 0 | V15: =U15/1.19 -> 0 | W15: =X15*1.19 -> 559899.76 | X15: 470504 | Y15: =-K15-L15-M15-N15+O15+P15+R15+T15+V15+X15 -> 1458814 | Z15: =VLOOKUP(D15,'Archivo con Bonos Ingresados '!V:CB,59,0) -> 1458814 | AA15: =Z15-Y15 -> 0 | AB15: =Y15*100/CU15 -> 3.2471129 | AC15: 30-01-2025 17:47:56 | AD15: 5969 | AE15: 18142681 | AF15: 0 | AG15: ALONSO DE CAMARGO 5870 DEPTO 403 | AI15: 99179180 | AK15: LAS CONDES | AL15: 01/01/1900 | AM15: NICOLAS.C¿MACCLUR@INPEN.CL | AO15: STATION WAGON | AQ15: CA35PR11 | AR15: GRIS PLATINO | AS15: WVGZZZCA5RC601451 | AT15: WVGZZZCA5RC601451 | AU15: NUEVO Y SIN USO | AV15: Parcial Facturada | AW15: 19949 | AX15: 31-01-2025 0:00:00 | AZ15: Factura Electrónica: 1841778 | BA15: 43474588 | BB15: 31-01-2025 0:00:00 | BD15: 0 | BE15: SALON | BF15: 31-01-2025 0:00:00 | BG15: CC | BH15: Peso | BJ15: 31 | BK15: 47050420 | BL15: -2521008 | BM15: -2521008 | BN15: 42008403 | BO15: 43474588 | BP15: -1466185 | BQ15: -3.49 % | BR15: 0 | BS15: 2749605 | BT15: 2749605 | BU15: 0 | BV15: 0 % | BW15: 110500 | BX15: 168487 | BY15: 0 | BZ15: 0 | CA15: 0 % | CB15: 0 | CC15: 0 | CD15: 0 | CE15: 0 | CF15: 0 % | CG15: 44529412 | CH15: 44926495 | CI15: 46224193 | CJ15: -1297698 | CK15: -2.89 % | CL15: -1297698 | CM15: -2.89 % | CN15: 0 | CO15: 0 | CP15: 52940105 | CQ15: 0 | CR15: 2749605 | CS15: 168487 | CT15: 52940104 | CU15: 44926495 | CV15: -1297698 | CW15: -2.89 % | CY15: 0 | DA15: 0 | DB15: 0 | DC15: 0
A16: CASA MATRIZ NUEVOS | B16: VOLKSWAGEN | C16: Taos TSI AT Highline 110KW/150CV | D16: AN-25-01-0011 | E16: 2025 | F16: 8AWBJ6B25RA840847 | G16: FRANCISCO JAVIER URETA ESTRADA | H16: ROBERTO LOBOS GUTIERREZ | I16: N | J16: Forum | K16: =BA16 -> 22640647 | L16: 175000 | M16: =BT16 -> 1196428 | P16: =CU16 -> 21608193 | Q16: =R16*1.19 -> 2850000 | R16: 2394958 | S16: =T16*1.19 -> 949999.61 | T16: 798319 | U16: 150000 | V16: =U16/1.19 -> 126050.42 | W16: =X16*1.19 -> 291899.86 | X16: 245294 | Y16: =-K16-L16-M16-N16+O16+P16+R16+T16+V16+X16 -> 1160739.4 | Z16: =VLOOKUP(D16,'Archivo con Bonos Ingresados '!V:CB,59,0) -> 1160739 | AA16: =Z16-Y16 -> -0.42016807 | AB16: =Y16*100/CU16 -> 5.3717561 | AC16: 10-01-2025 15:46:14 | AD16: 5913 | AE16: 17408406 | AF16: 8 | AG16: LAS VERBENAS 8485 DEPTO 713 B | AI16: 984295679 | AK16: LAS CONDES | AL16: 28/05/1990 | AM16: F.URETA.ES@GMAIL.COM | AO16: STATION WAGON 01 | AP16: FAMILIA 1 | AQ16: CQ17LY11 | AR16: BLANCO PURO | AS16: 8AWBJ6B25RA840847 | AT16: 8AWBJ6B25RA840847 | AU16: NUEVO Y SIN USO | AV16: Parcial Facturada | AW16: 19908 | AX16: 24-01-2025 0:00:00 | AZ16: Guía de Despacho: 1 - Factura Electrónica: 1864513 | BA16: 22640647 | BB16: 23-02-2025 0:00:00 | BD16: 0 | BE16: SALON | BF16: 23-02-2025 0:00:00 | BG16: CC | BH16: Peso | BI16: SZRZ28 | BJ16: -6 | BK16: 24529412 | BL16: -3571429 | BM16: -840336 | BN16: 20117647 | BO16: 22640647 | BP16: -2523000 | BQ16: -12.54 % | BR16: 0 | BS16: 1196428 | BT16: 1196428 | BU16: 0 | BV16: 0 % | BW16: 73920 | BX16: 294118 | BY16: 0 | BZ16: 0 | CA16: 0 % | CB16: 0 | CC16: 0 | CD16: 0 | CE16: 0 | CF16: 0 % | CG16: 20957983 | CH16: 21608193 | CI16: 23837075 | CJ16: -2228882 | CK16: -10.31 % | CL16: -2228882 | CM16: -10.31 % | CN16: 0 | CO16: 21557299 | CP16: 17178644 | CQ16: -13249515 | CR16: 1196428 | CS16: 294118 | CT16: 25486428 | CU16: 21608193 | CV16: -2228882 | CW16: -10.31 % | CY16: 0 | DA16: 0 | DB16: 0 | DC16: 0
A17: ANDES MOTOR | B17: JETOUR | C17: X70 1.5T MT STD | D17: AN-24-07-0010 | E17: 2024 | F17: LVUDB11B4PF009299 | G17: GERARDO ACHA ZUÑIGA | H17: Matias Larrain Larrain | I17: N | J17: BK | K17: =BA17 -> 12362017 | L17: 175000 | M17: =BT17 -> 622830 | P17: =CU17 -> 10579832 | Q17: 2000000 | R17: =Q17/1.19 -> 1680672.3 | S17: =T17*1.19 -> 0 | U17: 600000 | V17: =U17/1.19 -> 504201.68 | W17: =X17*1.19 -> 249999.96 | X17: 210084 | Y17: =-K17-L17-M17-N17+O17+P17+R17+T17+V17+X17 -> -185057.05 | Z17: =VLOOKUP(D17,'Archivo con Bonos Ingresados '!V:CB,59,0) -> -185057 | AA17: =Z17-Y17 -> 0.050420168 | AB17: =Y17*100/CU17 -> -1.7491492 | AC17: 15-01-2025 10:53:16 | AD17: 5929 | AE17: 7697564 | AF17: 7 | AG17: LOS JORNALEROS 1718 | AI17: 982342462 | AK17: ÑUÑOA | AL17: 06/03/1961 | AM17: GERARDOACHA@GMAIL.COM | AP17: X70 | AQ17: X70 1.5T MT STD | AR17: BLANCO | AS17: LVUDB11B4PF009299 | AT17: LVUDB11B4PF009299 | AU17: NUEVO Y SIN USO | AV17: Facturada | AW17: 19887 | AX17: 20-01-2025 0:00:00 | AZ17: Guía de Despacho: 1 - Factura Electrónica: 176302 | BA17: 12362017 | BB17: 19-02-2025 0:00:00 | BD17: 0 | BE17: SITIO WEB | BF17: 19-02-2025 0:00:00 | BG17: CI | BH17: Peso | BJ17: 202 | BK17: 13436975 | BL17: -2394958 | BM17: -462185 | BN17: 10579832 | BO17: 12362017 | BP17: -1782185 | BQ17: -16.85 % | BR17: -622830 | BS17: 0 | BT17: 622830 | BU17: -622830 | BV17: -100 % | BW17: 0 | BX17: 0 | BY17: 0 | BZ17: 0 | CA17: 0 % | CB17: 0 | CC17: 0 | CD17: 0 | CE17: 0 | CF17: 0 % | CG17: 11042017 | CH17: 10579832 | CI17: 12984847 | CJ17: -2405015 | CK17: -22.73 % | CL17: -2405015 | CM17: -22.73 % | CN17: 0 | CO17: 0 | CP17: 12672230 | CQ17: -82230 | CR17: 0 | CS17: 0 | CT17: 12590000 | CU17: 10579832 | CV17: -2405015 | CW17: -22.73 % | CY17: 0 | DA17: 0 | DB17: 0 | DC17: 0
A18: ANDES MOTOR | B18: MAXUS | C18: C35 L CARROCERÍA PLANA | D18: AN-24-12-0004 | E18: 2023 | F18: LSH14B4C6PD900042 | G18: GLOBAL GROUP INGENIERIA SPA | H18: Marcos Ignacio Campos Zavala | I18: N | J18: Directo | K18: =BA18 -> 15190500 | L18: 235000 | M18: =BT18 -> 573980 | P18: =CU18 -> 17120198 | Q18: =R18*1.19 -> 0 | S18: =T18*1.19 -> 0 | V18: =U18/1.19 -> 0 | W18: =X18*1.19 -> 0 | Y18: =-K18-L18-M18-N18+O18+P18+R18+T18+V18+X18 -> 1120718 | Z18: =VLOOKUP(D18,'Archivo con Bonos Ingresados '!V:CB,59,0) -> 1120718 | AA18: =Z18-Y18 -> 0 | AB18: =Y18*100/CU18 -> 6.5461743 | AC18: 07-01-2025 13:16:04 | AD18: 5897 | AE18: 76235534 | AF18: 5 | AG18: BAQUEDANO 239 OF 414 | AH18: 6-919.3266 | AI18: 926281759 | AK18: ANTOFAGASTA | AM18: GERENCIA@GGINGENIERIA.CL | AP18: C35 L | AQ18: C35 L CARROCERÍA PLANA | AR18: BLANCO | AS18: LSH14B4C6PD900042 | AT18: LSH14B4C6PD900042 | AU18: NUEVO Y SIN USO | AV18: Parcial Facturada | AW18: 19844 | AX18: 10-01-2025 0:00:00 | AZ18: Guía de Despacho: 1 - Factura Electrónica: 284604 | BA18: 15190500 | BB18: 10-01-2025 0:00:00 | BD18: 0 | BE18: WEB CONCESIONARIO | BF18: 10-01-2025 0:00:00 | BG18: RETAIL | BH18: Peso | BJ18: 15 | BK18: 20990000 | BL18: 0 | BM18: -4443782 | BN18: 16546218 | BO18: 15190500 | BP18: 1355718 | BQ18: 8.19 % | BR18: 0 | BS18: 573980 | BT18: 573980 | BU18: 0 | BV18: 0 % | BW18: 0 | BX18: 0 | BY18: 0 | BZ18: 0 | CA18: 0 % | CB18: 0 | CC18: 0 | CD18: 0 | CE18: 0 | CF18: 0 % | CG18: 20990000 | CH18: 17120198 | CI18: 15764480 | CJ18: 1355718 | CK18: 7.92 % | CL18: 1355718 | CM18: 7.92 % | CN18: 0 | CO18: 0 | CP18: 20263980 | CQ18: 0 | CR18: 573980 | CS18: 0 | CT18: 20263979 | CU18: 17120198 | CV18: 1355718 | CW18: 7.92 % | CY18: 0 | DA18: 0 | DB18: 0 | DC18: 0
A19: ANDES MOTOR | B19: JETOUR | C19: X70 1.5T MT LUX | D19: AN-23-08-0059 | E19: 2024 | F19: LVUDB11B8PF018233 | G19: HERWIN ROLANDO BAHAMONDES HENRIQUEZ | H19: Manuel Rodrigo Hurtado Melo | I19: N | J19: BK | K19: =BA19 -> 12748571 | L19: 175000 | M19: =BT19 -> 699835 | P19: =CU19 -> 11195633 | Q19: 2000000 | R19: =Q19/1.19 -> 1680672.3 | S19: =T19*1.19 -> 0 | U19: 1000000 | V19: =U19/1.19 -> 840336.13 | W19: 250000 | X19: =W19/1.19 -> 210084.03 | Y19: =-K19-L19-M19-N19+O19+P19+R19+T19+V19+X19 -> 303319.44 | Z19: =VLOOKUP(D19,'Archivo con Bonos Ingresados '!V:CB,59,0) -> 303319 | AA19: =Z19-Y19 -> -0.43697479 | AB19: =Y19*100/CU19 -> 2.7092656 | AC19: 02-01-2025 17:00:38 | AD19: 5885 | AE19: 13161261 | AF19: 3 | AG19: PASAJE LA GROSSAL 02340 | AI19: 993401676 | AK19: SAN BERNARDO | AL19: 07/06/1977 | AM19: HEREBAHAM@HOTMAIL.COM | AP19: X70 | AQ19: X70 1.5T MT LUX | AR19: ROJO | AS19: LVUDB11B8PF018233 | AT19: LVUDB11B8PF018233 | AU19: NUEVO Y SIN USO | AV19: Parcial Facturada | AW19: 19886 | AX19: 17-01-2025 0:00:00 | AZ19: Guía de Despacho: 1 - Factura Electrónica: 145309 | BA19: 12748571 | BB19: 16-02-2025 0:00:00 | BD19: 0 | BE19: SITIO WEB | BF19: 16-02-2025 0:00:00 | BG19: CC | BH19: Peso | BI19: HLRT60 | BJ19: 506 | BK19: 14697479 | BL19: -2521008 | BM19: -1680672 | BN19: 10495798 | BO19: 12748571 | BP19: -2252773 | BQ19: -21.46 % | BR19: 0 | BS19: 699835 | BT19: 699835 | BU19: 0 | BV19: 0 % | BW19: 0 | BX19: 0 | BY19: 0 | BZ19: 0 | CA19: 0 % | CB19: 0 | CC19: 0 | CD19: 0 | CE19: 0 | CF19: 0 % | CG19: 12176471 | CH19: 11195633 | CI19: 13448406 | CJ19: -2252773 | CK19: -20.12 % | CL19: -2252773 | CM19: -20.12 % | CN19: 0 | CO19: 3500000 | CP19: 9738652 | CQ19: -48817 | CR19: 699835 | CS19: 0 | CT19: 13189835 | CU19: 11195633 | CV19: -2252773 | CW19: -20.12 % | CY19: 0 | DA19: 0 | DB19: 0 | DC19: 0
A20: CASA MATRIZ NUEVOS | B20: VOLKSWAGEN | C20: Saveiro 1.6 MT Cabina Doble Lite | D20: AN-24-10-0057 | E20: 2025 | F20: 9BWJL45U7SP006599 | G20: INTELCLIMA LIMITADA | H20: JUAN PABLO GONZALEZ ACUÑA | I20: N | J20: Lucy | K20: =BA20 -> 12096160 | L20: 90000 | M20: =BT20 -> 328487 | P20: =CU20 -> 11076386 | Q20: =R20*1.19 -> 1606500 | R20: 1350000 | S20: =T20*1.19 -> 0 | U20: 150000 | V20: =U20/1.19 -> 126050.42 | W20: 500000 | X20: =W20/1.19 -> 420168.07 | Y20: =-K20-L20-M20-N20+O20+P20+R20+T20+V20+X20 -> 457957.49 | Z20: =VLOOKUP(D20,'Archivo con Bonos Ingresados '!V:CB,59,0) -> 37789 | AA20: =Z20-Y20 -> -420168.49 | AB20: =Y20*100/CU20 -> 4.1345389 | AC20: 21-01-2025 15:24:14 | AD20: 5946 | AE20: 76431332 | AF20: 1 | AG20: FEDERICO ERRAZURIZ 1250 DPTO 31 EDIFICIO 6 | AH20: 955290099 | AK20: PUDAHUEL | AM20: s.ramireztorres@hotmail.com | AO20: CAMIONETA | AP20: SAVEIRO | AQ20: 5UKWT412 | AR20: BLANCO CANDY | AS20: 9BWJL45U7SP006599 | AT20: 9BWJL45U7SP006599 | AU20: NUEVO Y SIN USO | AV20: Facturada | AW20: 19943 | AX20: 30-01-2025 0:00:00 | AZ20: Guía de Despacho: 1 - Factura Electrónica: 1839953 - Nota de Crédito Electrónica: 3062524 | BA20: 12096160 | BB20: 01-03-2025 0:00:00 | BD20: 0 | BE20: SALON | BF20: 01-03-2025 0:00:00 | BG20: FLOTA | BH20: Peso | BI20: PGSY19 | BJ20: 98 | BK20: 13840000 | BL20: -2150000 | BM20: -942101 | BN20: 10747899 | BO20: 10746160 | BP20: 1739 | BQ20: 0.02 % | BR20: 0 | BS20: 328487 | BT20: 328487 | BU20: 0 | BV20: 0 % | BW20: 0 | BX20: 0 | BY20: 0 | BZ20: 0 | CA20: 0 % | CB20: 0 | CC20: 0 | CD20: 0 | CE20: 0 | CF20: 0 % | CG20: 11690000 | CH20: 11076386 | CI20: 11074647 | CJ20: 1739 | CK20: 0.02 % | CL20: 1739 | CM20: 0.02 % | CN20: 0 | CO20: 9000000 | CP20: 10709913 | CQ20: -6591426 | CR20: 328487 | CS20: 0 | CT20: 13118487 | CU20: 11076386 | CV20: 1739 | CW20: 0.02 % | CY20: 0 | DA20: 0 | DB20: 1606500 | DC20: 0
A21: CASA MATRIZ NUEVOS | B21: VOLKSWAGEN | C21: Saveiro 1.6 MT Cabina Simple Lite | D21: AN-25-01-0028 | E21: 2025 | F21: 9BWKL45U3SP047879 | G21: INTELCLIMA LIMITADA | H21: JUAN PABLO GONZALEZ ACUÑA | I21: G | J21: BK | K21: =BA21 -> 11287520 | L21: 90000 | M21: =BT21 -> 295713 | P21: =CU21 -> 9951175 | Q21: =R21*1.19 -> 1487500 | R21: 1250000 | S21: =T21*1.19 -> 0 | V21: =U21/1.19 -> 0 | W21: =X21*1.19 -> 0 | Y21: =-K21-L21-M21-N21+O21+P21+R21+T21+V21+X21 -> -472058 | Z21: =VLOOKUP(D21,'Archivo con Bonos Ingresados '!V:CB,59,0) -> -472058 | AA21: =Z21-Y21 -> 0 | AB21: =Y21*100/CU21 -> -4.7437413 | AC21: 21-01-2025 15:32:21 | AD21: 5947 | AE21: 76431332 | AF21: 1 | AG21: FEDERICO ERRAZURIZ 1250 DPTO 31 EDIFICIO 6 | AH21: 955290099 | AK21: PUDAHUEL | AM21: s.ramireztorres@hotmail.com | AO21: CAMIONETA | AP21: SAVEIRO | AQ21: 5URTT412 | AR21: BLANCO CANDY | AS21: 9BWKL45U3SP047879 | AT21: 9BWKL45U3SP047879 | AU21: NUEVO Y SIN USO | AV21: Facturada | AW21: 19944 | AX21: 30-01-2025 0:00:00 | AZ21: Guía de Despacho: 1 - Factura Electrónica: 1864567 - Nota de Crédito Electrónica: 3063712 | BA21: 11287520 | BB21: 01-03-2025 0:00:00 | BD21: 0 | BE21: SALON | BF21: 01-03-2025 0:00:00 | BG21: FLOTA | BH21: Peso | BJ21: 8 | BK21: 12640000 | BL21: -2050000 | BM21: -934538 | BN21: 9655462 | BO21: 11287520 | BP21: -1632058 | BQ21: -16.9 % | BR21: 0 | BS21: 295713 | BT21: 295713 | BU21: 0 | BV21: 0 % | BW21: 0 | BX21: 0 | BY21: 0 | BZ21: 0 | CA21: 0 % | CB21: 0 | CC21: 0 | CD21: 0 | CE21: 0 | CF21: 0 % | CG21: 10590000 | CH21: 9951175 | CI21: 11583233 | CJ21: -1632058 | CK21: -16.4 % | CL21: -1632058 | CM21: -16.4 % | CN21: 0 | CO21: 0 | CP21: 11785713 | CQ21: 0 | CR21: 295713 | CS21: 0 | CT21: 11785713 | CU21: 9951175 | CV21: -1632058 | CW21: -16.4 % | CY21: 0 | DA21: 0 | DB21: 0 | DC21: 0
A22: CASA MATRIZ NUEVOS | B22: VOLKSWAGEN | C22: Saveiro 1.6 MT Cabina Simple Lite | D22: AN-25-01-0026 | E22: 2025 | F22: 9BWKL45U1SP048416 | G22: INTELCLIMA LIMITADA | H22: JUAN PABLO GONZALEZ ACUÑA | I22: G | J22: Forum | K22: =BA22 -> 11287520 | L22: 90000 | M22: =BT22 -> 295713 | P22: =CU22 -> 9951175 | Q22: =R22*1.19 -> 1487500 | R22: 1250000 | S22: =T22*1.19 -> 651999.81 | T22: 547899 | U22: 150000 | V22: =U22/1.19 -> 126050.42 | W22: =X22*1.19 -> 0 | Y22: =-K22-L22-M22-N22+O22+P22+R22+T22+V22+X22 -> 201891.42 | Z22: =VLOOKUP(D22,'Archivo con Bonos Ingresados '!V:CB,59,0) -> 201891 | AA22: =Z22-Y22 -> -0.42016807 | AB22: =Y22*100/CU22 -> 2.0288199 | AC22: 21-01-2025 15:51:21 | AD22: 5948 | AE22: 76431332 | AF22: 1 | AG22: FEDERICO ERRAZURIZ 1250 DPTO 31 EDIFICIO 6 | AH22: 955290099 | AK22: PUDAHUEL | AM22: s.ramireztorres@hotmail.com | AO22: CAMIONETA | AP22: SAVEIRO | AQ22: 5URTT412 | AR22: BLANCO CANDY | AS22: 9BWKL45U1SP048416 | AT22: 9BWKL45U1SP048416 | AU22: NUEVO Y SIN USO | AV22: Facturada | AW22: 19945 | AX22: 30-01-2025 0:00:00 | AZ22: Guía de Despacho: 1 - Factura Electrónica: 1864566 - Nota de Crédito Electrónica: 3063693 | BA22: 11287520 | BB22: 01-03-2025 0:00:00 | BD22: 0 | BE22: SALON | BF22: 01-03-2025 0:00:00 | BG22: FLOTA | BH22: Peso | BJ22: 8 | BK22: 13840000 | BL22: -2050000 | BM22: -934538 | BN22: 9655462 | BO22: 9937520 | BP22: -282058 | BQ22: -2.92 % | BR22: 0 | BS22: 295713 | BT22: 295713 | BU22: 0 | BV22: 0 % | BW22: 0 | BX22: 0 | BY22: 0 | BZ22: 0 | CA22: 0 % | CB22: 0 | CC22: 0 | CD22: 0 | CE22: 0 | CF22: 0 % | CG22: 11790000 | CH22: 9951175 | CI22: 10233233 | CJ22: -282058 | CK22: -2.83 % | CL22: -282058 | CM22: -2.83 % | CN22: 0 | CO22: 0 | CP22: 11785713 | CQ22: 0 | CR22: 295713 | CS22: 0 | CT22: 11785713 | CU22: 9951175 | CV22: -282058 | CW22: -2.83 % | CY22: 0 | DA22: 0 | DB22: 1606500 | DC22: 0
A23: CASA MATRIZ NUEVOS | B23: VOLKSWAGEN | C23: Taos TSI AT Highline 110KW/150CV | D23: AN-25-01-0003 | E23: 2025 | F23: 8AWBJ6B28RA828840 | G23: JENNY PAOLA LLEWELLYN ROVEGNO | H23: JUAN PABLO GONZALEZ ACUÑA | I23: N | J23: Forum | K23: =BA23 -> 22640647 | L23: 175000 | M23: =BT23 -> 1186750 | P23: =CU23 -> 21163557 | Q23: =R23*1.19 -> 2850000 | R23: 2394958 | S23: =T23*1.19 -> 949999.61 | T23: 798319 | U23: 150000 | V23: =U23/1.19 -> 126050.42 | W23: =X23*1.19 -> 291899.86 | X23: 245294 | Y23: =-K23-L23-M23-N23+O23+P23+R23+T23+V23+X23 -> 725781.42 | Z23: =VLOOKUP(D23,'Archivo con Bonos Ingresados '!V:CB,59,0) -> 725781 | AA23: =Z23-Y23 -> -0.42016807 | AB23: =Y23*100/CU23 -> 3.4293924 | AC23: 06-01-2025 11:01:03 | AD23: 5891 | AE23: 10265209 | AF23: 6 | AG23: DOCTOR ROBERTO DEL RIO 1771 DPTO 401 | AH23: 997991954 | AK23: PROVIDENCIA | AL23: 07/05/1972 | AM23: jenny.llewelyn@gmail.com | AO23: STATION WAGON 01 | AP23: FAMILIA 1 | AQ23: CQ17LY11 | AR23: GRIS INDIO METALIZADO | AS23: 8AWBJ6B28RA828840 | AU23: NUEVO Y SIN USO | AV23: Facturada | AW23: 19823 | AX23: 06-01-2025 0:00:00 | AZ23: Guía de Despacho: 1 - Factura Electrónica: 1842389 | BA23: 22640647 | BB23: 06-01-2025 0:00:00 | BD23: 0 | BE23: SALON | BF23: 06-01-2025 0:00:00 | BG23: RETAIL | BH23: Peso | BI23: JVGP11 | BJ23: 0 | BK23: 24529412 | BL23: -3571429 | BM23: -981176 | BN23: 19976807 | BO23: 22640647 | BP23: -2663840 | BQ23: -13.33 % | BR23: 0 | BS23: 1186750 | BT23: 1186750 | BU23: 0 | BV23: 0 % | BW23: 0 | BX23: 0 | BY23: 0 | BZ23: 0 | CA23: 0 % | CB23: 0 | CC23: 0 | CD23: 0 | CE23: 0 | CF23: 0 % | CG23: 20957983 | CH23: 21163557 | CI23: 23827397 | CJ23: -2663840 | CK23: -12.59 % | CL23: -2663840 | CM23: -12.59 % | CN23: 0 | CO23: 11000000 | CP23: 13959150 | CQ23: 0 | CR23: 1186750 | CS23: 0 | CT23: 24959150 | CU23: 21163557 | CV23: -2663840 | CW23: -12.59 % | CY23: 0 | DA23: 0 | DB23: 0 | DC23: 0
A24: CASA MATRIZ NUEVOS | B24: VOLKSWAGEN | C24: Nivus 1.0 TSI AT Comfortline 85KW/116CV 5 p | D24: AN-24-10-0040 | E24: 2025 | F24: 9BWCH6CH5RP048825 | G24: JONNY KULKA FRAENKEL | H24: ROBERTO LOBOS GUTIERREZ | I24: N | J24: Directo | K24: =BA24 -> 16396017 | L24: 145000 | M24: =BT24 -> 844500 | P24: =CU24 -> 15672651 | Q24: =R24*1.19 -> 2199999.4 | R24: 1848739 | S24: =T24*1.19 -> 0 | V24: =U24/1.19 -> 0 | W24: =X24*1.19 -> 208899.74 | X24: 175546 | Y24: =-K24-L24-M24-N24+O24+P24+R24+T24+V24+X24 -> 311419 | Z24: =VLOOKUP(D24,'Archivo con Bonos Ingresados '!V:CB,59,0) -> 311419 | AA24: =Z24-Y24 -> 0 | AB24: =Y24*100/CU24 -> 1.9870219 | AC24: 22-01-2025 17:41:25 | AD24: 5951 | AE24: 4863497 | AF24: 4 | AG24: CAMINO OTOÑAL 1326 DPTO C2 | AH24: 993300005 | AK24: LAS CONDES | AL24: 21/04/1945 | AM24: MARCOS.KULKA@FCH.CL | AO24: STATION WAGON | AP24: FAMILIA 1 | AQ24: CH13K311 | AR24: BLANCO CANDY | AS24: 9BWCH6CH5RP048825 | AT24: 9BWCH6CH5RP048825 | AU24: NUEVO Y SIN USO | AV24: Facturada | AW24: 19924 | AX24: 27-01-2025 0:00:00 | AZ24: Guía de Despacho: 1 - Factura Electrónica: 1839682 | BA24: 16396017 | BB24: 27-01-2025 0:00:00 | BD24: 0 | BE24: WEB CONCESIONARIO | BF24: 27-01-2025 0:00:00 | BG24: CC | BH24: Peso | BJ24: 0 | BK24: 17134454 | BL24: -1848739 | BM24: -457563 | BN24: 14828151 | BO24: 16396017 | BP24: -1567866 | BQ24: -10.57 % | BR24: 0 | BS24: 844500 | BT24: 844500 | BU24: 0 | BV24: 0 % | BW24: 0 | BX24: 0 | BY24: 0 | BZ24: 0 | CA24: 0 % | CB24: 0 | CC24: 0 | CD24: 0 | CE24: 0 | CF24: 0 % | CG24: 15285715 | CH24: 15672651 | CI24: 17240517 | CJ24: -1567866 | CK24: -10 % | CL24: -1567866 | CM24: -10 % | CN24: 0 | CO24: 0 | CP24: 18490000 | CQ24: 0 | CR24: 844500 | CS24: 0 | CT24: 18490000 | CU24: 15672651 | CV24: -1567866 | CW24: -10 % | CY24: 0 | DA24: 0 | DB24: 0 | DC24: 0
A25: ANDES MOTOR | B25: KARRY | C25: Q22 C.B. Cargo Box 1.5cc | D25: AN-25-01-0036 | E25: 2023 | F25: LVM1A1A14NF048727 | G25: LION OPERATIONS SPA | H25: Marcos Ignacio Campos Zavala | I25: N | J25: Directo | K25: =BA25 -> 9380600 | L25: 75000 | M25: =BT25 -> 336980 | P25: =CU25 -> 7891602 | Q25: =R25*1.19 -> 2677500 | R25: 2250000 | S25: =T25*1.19 -> 0 | V25: =U25/1.19 -> 0 | W25: =X25*1.19 -> 0 | Y25: =-K25-L25-M25-N25+O25+P25+R25+T25+V25+X25 -> 349022 | Z25: =VLOOKUP(D25,'Archivo con Bonos Ingresados '!V:CB,59,0) -> 349022 | AA25: =Z25-Y25 -> 0 | AB25: =Y25*100/CU25 -> 4.4227015 | AC25: 24-01-2025 10:01:06 | AD25: 5956 | AE25: 78060017 | AF25: 9 | AG25: SEMINARIO 372 | AI25: 985290198 | AK25: PUERTO MONTT | AM25: gabriel.oberreuter@opciones.cl | AP25: Q22 | AQ25: Q22 C.B. Cargo Box 1.5cc | AR25: BLANCO | AS25: LVM1A1A14NF048727 | AT25: LVM1A1A14NF048727 | AU25: NUEVO Y SIN USO | AV25: Parcial Facturada | AW25: 19950 | AX25: 31-01-2025 0:00:00 | AZ25: Guía de Despacho: 1 - Factura Electrónica: 293476 | BA25: 9380600 | BB25: 31-01-2025 0:00:00 | BD25: 0 | BE25: WEB CONCESIONARIO | BF25: 31-01-2025 0:00:00 | BG25: FLOTA | BH25: Peso | BJ25: -6 | BK25: 10540000 | BL25: -2250000 | BM25: -735378 | BN25: 7554622 | BO25: 9380600 | BP25: -1825978 | BQ25: -24.17 % | BR25: 0 | BS25: 336980 | BT25: 336980 | BU25: 0 | BV25: 0 % | BW25: 0 | BX25: 0 | BY25: 0 | BZ25: 0 | CA25: 0 % | CB25: 0 | CC25: 0 | CD25: 0 | CE25: 0 | CF25: 0 % | CG25: 8290000 | CH25: 7891602 | CI25: 9717580 | CJ25: -1825978 | CK25: -23.14 % | CL25: -1825978 | CM25: -23.14 % | CN25: 0 | CO25: 0 | CP25: 9326980 | CQ25: 0 | CR25: 336980 | CS25: 0 | CT25: 9326980 | CU25: 7891602 | CV25: -1825978 | CW25: -23.14 % | CY25: 0 | DA25: 0 | DB25: 0 | DC25: 0
A26: CASA MATRIZ NUEVOS | B26: VOLKSWAGEN | C26: SAVEIRO 1.6 MT CABINA DOBLE 81 kW/110 CV | D26: AN-24-06-0030 | E26: 2025 | F26: 9BWJL45U1SP003018 | G26: LIQUI MOLY CHILE S.A | H26: JUAN PABLO GONZALEZ ACUÑA | I26: N | J26: Directo | K26: =BA26 -> 13054340 | L26: 90000 | M26: =BT26 -> 485138 | P26: =CU26 -> 13454738 | Q26: =R26*1.19 -> 1263708.6 | R26: 1061940 | S26: =T26*1.19 -> 164291.4 | T26: 138060 | V26: =U26/1.19 -> 0 | W26: =X26*1.19 -> 0 | Y26: =-K26-L26-M26-N26+O26+P26+R26+T26+V26+X26 -> 1025260 | Z26: =VLOOKUP(D26,'Archivo con Bonos Ingresados '!V:CB,59,0) -> 1025260 | AA26: =Z26-Y26 -> 0 | AB26: =Y26*100/CU26 -> 7.6200666 | AC26: 16-01-2025 10:16:04 | AD26: 5934 | AE26: 86868900 | AF26: 5 | AG26: ELIODORO YAÑEZ 1727 | AH26: 984188185 | AK26: PROVIDENCIA | AL26: 01/01/1900 | AM26: info@liqui-moly.cl | AO26: CAMIONETA | AP26: FAMILIA 1 | AQ26: 5UKWT413 | AR26: BLANCO CANDY | AS26: 9BWJL45U1SP003018 | AT26: 9BWJL45U1SP003018 | AU26: NUEVO Y SIN USO | AV26: Parcial Facturada | AW26: 19884 | AX26: 17-01-2025 0:00:00 | AZ26: Guía de Despacho: 1 - Factura Electrónica: 1791013 - Nota de Crédito Electrónica: 3060477 - Nota de Crédito Electrónica: 3060548 | BA26: 13054340 | BB26: 17-01-2025 0:00:00 | BD26: 0 | BE26: SALON | BF26: 17-01-2025 0:00:00 | BG26: FLOTA | BH26: Peso | BJ26: 0 | BK26: 15340000 | BL26: -1450000 | BM26: -920400 | BN26: 12969600 | BO26: 11854340 | BP26: 1115260 | BQ26: 8.6 % | BR26: 0 | BS26: 485138 | BT26: 485138 | BU26: 0 | BV26: 0 % | BW26: 0 | BX26: 0 | BY26: 0 | BZ26: 0 | CA26: 0 % | CB26: 0 | CC26: 0 | CD26: 0 | CE26: 0 | CF26: 0 % | CG26: 13890000 | CH26: 13454738 | CI26: 12339478 | CJ26: 1115260 | CK26: 8.29 % | CL26: 1115260 | CM26: 8.29 % | CN26: 0 | CO26: 0 | CP26: 15918962 | CQ26: 0 | CR26: 485138 | CS26: 0 | CT26: 15918962 | CU26: 13454738 | CV26: 1115260 | CW26: 8.29 % | CY26: 0 | DA26: 0 | DB26: 1428000 | DC26: 0
A27: CASA MATRIZ NUEVOS | B27: VOLKSWAGEN | C27: T-Cross 1.0 TSI AT Comfortline - 85 kW/116 CV | D27: AN-24-08-0075 | E27: 2025 | F27: 9BWBH6BF0S4003522 | G27: LUIS ALEJANDRO REINOSO MEDINELLI | H27: JUAN PABLO GONZALEZ ACUÑA | I27: N | J27: Directo | K27: =BA27 -> 16812766 | L27: 175000 | M27: =BT27 -> 921320 | P27: =CU27 -> 16877496 | Q27: =R27*1.19 -> 1749999.7 | R27: 1470588 | S27: =T27*1.19 -> 0 | V27: =U27/1.19 -> 0 | W27: =X27*1.19 -> 214899.72 | X27: 180588 | Y27: =-K27-L27-M27-N27+O27+P27+R27+T27+V27+X27 -> 619586 | Z27: =VLOOKUP(D27,'Archivo con Bonos Ingresados '!V:CB,59,0) -> 619586 | AA27: =Z27-Y27 -> 0 | AB27: =Y27*100/CU27 -> 3.6710777 | AC27: 02-01-2025 12:13:45 | AD27: 5884 | AE27: 8133978 | AF27: 3 | AG27: MARCEL DUHAUT 2977 DPTO 501 | AH27: 988993993 | AK27: PROVIDENCIA | AL27: 10/08/1967 | AM27: areinoso@uc.cl | AO27: STATION WAGON | AP27: T CROSS | AQ27: BF33K311 | AR27: AZUL NORUEGA | AS27: 9BWBH6BF0S4003522 | AT27: 9BWBH6BF0S4003522 | AU27: NUEVO Y SIN USO | AV27: Facturada | AW27: 19842 | AX27: 09-01-2025 0:00:00 | AZ27: Guía de Despacho: 1 - Factura Electrónica: 1838074 | BA27: 16812766 | BB27: 09-01-2025 0:00:00 | BD27: 0 | BE27: SALON | BF27: 09-01-2025 0:00:00 | BG27: RETAIL | BH27: Peso | BJ27: 0 | BK27: 18058824 | BL27: -1470588 | BM27: -632059 | BN27: 15956176 | BO27: 16812766 | BP27: -856590 | BQ27: -5.37 % | BR27: 0 | BS27: 921320 | BT27: 921320 | BU27: 0 | BV27: 0 % | BW27: 0 | BX27: 0 | BY27: 0 | BZ27: 0 | CA27: 0 % | CB27: 0 | CC27: 0 | CD27: 0 | CE27: 0 | CF27: 0 % | CG27: 16588236 | CH27: 16877496 | CI27: 17734086 | CJ27: -856590 | CK27: -5.08 % | CL27: -856590 | CM27: -5.08 % | CN27: 0 | CO27: 0 | CP27: 19909170 | CQ27: 0 | CR27: 921320 | CS27: 0 | CT27: 19909169 | CU27: 16877496 | CV27: -856590 | CW27: -5.08 % | CY27: 0 | DA27: 0 | DB27: 0 | DC27: 0
A28: ANDES MOTOR | B28: JETOUR | C28: T2 2.0T GDI AWD 7DCT LIMITED | D28: AN-24-08-0067 | E28: 2025 | F28: HJRPBGJBXSB200369 | G28: MANUELA SOLEDAD SALAS CAMPOS | H28: Marcos Ignacio Campos Zavala | I28: N | J28: BK | K28: =BA28 -> 23185546 | L28: 175000 | M28: =BT28 -> 1572888 | P28: =CU28 -> 24637090 | Q28: 400000 | R28: =Q28/1.19 -> 336134.45 | S28: =T28*1.19 -> 0 | U28: 1000000 | V28: =U28/1.19 -> 840336.13 | W28: =X28*1.19 -> 0 | Y28: =-K28-L28-M28-N28+O28+P28+R28+T28+V28+X28 -> 880126.59 | Z28: =VLOOKUP(D28,'Archivo con Bonos Ingresados '!V:CB,59,0) -> 880127 | AA28: =Z28-Y28 -> 0.41176471 | AB28: =Y28*100/CU28 -> 3.5723642 | AC28: 21-01-2025 14:49:46 | AD28: 5945 | AE28: 17958247 | AF28: 3 | AG28: JUAN DE DIOS VIAL CORREA 4220 DPTO 401 B | AH28: 95975802 | AI28: 951975802 | AK28: PEÑALOLEN | AL28: 10/06/1991 | AM28: manu_salas1991@hotmail.com | AP28: T2 | AQ28: T2 2.0T GDI AWD 7DCT LIMITED | AR28: GRIS ARENA | AS28: HJRPBGJBXSB200369 | AT28: HJRPBGJBXSB200369 | AU28: NUEVO Y SIN USO | AV28: Parcial Facturada | AW28: 19957 | AX28: 31-01-2025 0:00:00 | AZ28: Guía de Despacho: 1 - Factura Electrónica: 187112 | BA28: 23185546 | BB28: 02-03-2025 0:00:00 | BD28: 0 | BE28: WEB CONCESIONARIO | BF28: 02-03-2025 0:00:00 | BG28: RETAIL | BH28: Peso | BI28: SFXJ73 | BJ28: 158 | BK28: 25201681 | BL28: -1176471 | BM28: -961008 | BN28: 23064202 | BO28: 23185546 | BP28: -121344 | BQ28: -0.53 % | BR28: 0 | BS28: 1572888 | BT28: 1572888 | BU28: 0 | BV28: 0 % | BW28: 0 | BX28: 0 | BY28: 0 | BZ28: 0 | CA28: 0 % | CB28: 0 | CC28: 0 | CD28: 0 | CE28: 0 | CF28: 0 % | CG28: 24025210 | CH28: 24637090 | CI28: 24758434 | CJ28: -121344 | CK28: -0.49 % | CL28: -121344 | CM28: -0.49 % | CN28: 0 | CO28: 6700000 | CP28: 24798063 | CQ28: -2478775 | CR28: 1572888 | CS28: 0 | CT28: 29019288 | CU28: 24637090 | CV28: -121344 | CW28: -0.49 % | CY28: 0 | DA28: 0 | DB28: 0 | DC28: 0
A29: CASA MATRIZ NUEVOS | B29: VOLKSWAGEN | C29: SAVEIRO 1.6 MT CABINA SIMPLE | D29: AN-24-11-0083 | E29: 2025 | F29: 9BWKL45U5SP024555 | G29: MAQUINARIAS FABIAN GALLARDO, E.I.R.L | H29: ROBERTO LOBOS GUTIERREZ | I29: N | J29: Lucy | K29: =BA29 -> 12358360 | L29: 90000 | M29: =BT29 -> 338823 | P29: =CU29 -> 11431260 | Q29: =R29*1.19 -> 1963500 | R29: 1650000 | S29: =T29*1.19 -> 651999.81 | T29: 547899 | U29: 150000 | V29: =U29/1.19 -> 126050.42 | W29: =X29*1.19 -> 0 | Y29: =-K29-L29-M29-N29+O29+P29+R29+T29+V29+X29 -> 968026.42 | Z29: =VLOOKUP(D29,'Archivo con Bonos Ingresados '!V:CB,59,0) -> 968026 | AA29: =Z29-Y29 -> -0.42016807 | AB29: =Y29*100/CU29 -> 8.468239 | AC29: 09-01-2025 17:40:31 | AD29: 5906 | AE29: 76096975 | AF29: 3 | AG29: COSTANERA DEL ESTRECHO 01934 EL GOLF | AI29: 56977082136 | AK29: PUNTA ARENAS | AL29: 01/01/1900 | AM29: Fgallardo@fgmaq.cl | AO29: CAMIONETA | AP29: SAVEIRO | AQ29: 5URTT413 | AR29: PLATA SIRIUS | AS29: 9BWKL45U5SP024555 | AT29: 9BWKL45U5SP024555 | AU29: NUEVO Y SIN USO | AV29: Facturada | AW29: 19895 | AX29: 22-01-2025 0:00:00 | AZ29: Guía de Despacho: 1 - Factura Electrónica: 1840962 - Nota de Crédito Electrónica: 3062488 | BA29: 12358360 | BB29: 21-02-2025 0:00:00 | BD29: 0 | BE29: WEB CONCESIONARIO | BF29: 21-02-2025 0:00:00 | BG29: CI | BH29: Peso | BJ29: 0 | BK29: 0 | BL29: -2450000 | BM29: -597563 | BN29: 11092437 | BO29: 10708360 | BP29: 384077 | BQ29: 3.46 % | BR29: 0 | BS29: 338823 | BT29: 338823 | BU29: 0 | BV29: 0 % | BW29: 0 | BX29: 0 | BY29: 0 | BZ29: 0 | CA29: 0 % | CB29: 0 | CC29: 0 | CD29: 0 | CE29: 0 | CF29: 0 % | CG29: -2450000 | CH29: 11431260 | CI29: 11047183 | CJ29: 384077 | CK29: 3.36 % | CL29: 384077 | CM29: 3.36 % | CN29: 0 | CO29: 0 | CP29: 13538823 | CQ29: 0 | CR29: 338823 | CS29: 0 | CT29: 13538823 | CU29: 11431260 | CV29: 384077 | CW29: 3.36 % | CY29: 0 | DA29: 0 | DB29: 1963500 | DC29: 0
A30: CASA MATRIZ NUEVOS | B30: VOLKSWAGEN | C30: Nivus 1.0 TSI AT Comfortline 85KW/116CV 5 p | D30: AN-24-03-0040 | E30: 2024 | F30: 9BWCH6CH3PP006182 | G30: MARIA DE LOS ANGELES RENARD MERINO | H30: ROBERTO LOBOS GUTIERREZ | I30: V | J30: Directo | K30: =BA30 -> 15695160 | L30: 145000 | M30: =BT30 -> 491389 | P30: =CU30 -> 13928364 | Q30: =R30*1.19 -> 4673400.1 | R30: 3927227 | S30: =T30*1.19 -> 0 | V30: =U30/1.19 -> 0 | W30: =X30*1.19 -> 0 | Y30: =-K30-L30-M30-N30+O30+P30+R30+T30+V30+X30 -> 1524042 | Z30: =VLOOKUP(D30,'Archivo con Bonos Ingresados '!V:CB,59,0) -> 1524042 | AA30: =Z30-Y30 -> 0 | AB30: =Y30*100/CU30 -> 10.942003 | AC30: 11-01-2025 11:47:26 | AD30: 5914 | AE30: 8966208 | AF30: 7 | AG30: GENERAL BLANCHE 10226 | AI30: 998273729 | AK30: LAS CONDES | AL30: 01/01/1900 | AM30: MRENARD@YUKEN.CL | AO30: STATION WAGON | AP30: FAMILIA 1 | AQ30: CH13K311 | AR30: BLANCO CANDY | AS30: 9BWCH6CH3PP006182 | AT30: 9BWCH6CH3PP006182 | AU30: NUEVO Y SIN USO | AV30: Facturada | AW30: 19860 | AX30: 14-01-2025 0:00:00 | AZ30: Guía de Despacho Electrónica: 1 - Factura Electrónica: 1788757 - Nota de Crédito Electrónica: 3058060 | BA30: 15695160 | BB30: 14-01-2025 0:00:00 | BD30: 0 | BE30: SALON | BF30: 14-01-2025 0:00:00 | BG30: CC | BH30: Peso | BJ30: 0 | BK30: 17134454 | BL30: -3697479 | BM30: 0 | BN30: 13436975 | BO30: 15695160 | BP30: -2258185 | BQ30: -16.81 % | BR30: 0 | BS30: 491389 | BT30: 491389 | BU30: 0 | BV30: 0 % | BW30: 0 | BX30: 0 | BY30: 0 | BZ30: 0 | CA30: 0 % | CB30: 0 | CC30: 0 | CD30: 0 | CE30: 0 | CF30: 0 % | CG30: 13436975 | CH30: 13928364 | CI30: 16186549 | CJ30: -2258185 | CK30: -16.21 % | CL30: -2258185 | CM30: -16.21 % | CN30: 0 | CO30: 0 | CP30: 16481389 | CQ30: 0 | CR30: 491389 | CS30: 0 | CT30: 16481389 | CU30: 13928364 | CV30: -2258185 | CW30: -16.21 % | CY30: 0 | DA30: 0 | DB30: 0 | DC30: 0
A31: CASA MATRIZ NUEVOS | B31: VOLKSWAGEN | C31: POLO 1.0 TSI HIGHLINE AT | D31: AN-24-06-0015 | E31: 2024 | F31: 9BWAH5BZ8ST602190 | G31: MARIA JOSE VIELMA ZANDOVAL | H31: CLAUDIO ROBLEZ GALAZ | I31: V | J31: Directo | K31: =BA31 -> 14537722 | L31: 90000 | M31: =BT31 -> 489290 | P31: =CU31 -> 13523500 | Q31: =R31*1.19 -> 2239400.3 | R31: 1881849 | S31: =T31*1.19 -> 0 | V31: =U31/1.19 -> 0 | W31: =X31*1.19 -> 0 | Y31: =-K31-L31-M31-N31+O31+P31+R31+T31+V31+X31 -> 288337 | Z31: =VLOOKUP(D31,'Archivo con Bonos Ingresados '!V:CB,59,0) -> 288337 | AA31: =Z31-Y31 -> 0 | AB31: =Y31*100/CU31 -> 2.1321182 | AC31: 08-01-2025 13:23:44 | AD31: 5899 | AE31: 20465426 | AF31: 3 | AG31: CAMINO LAS CUMBRE 6838 CASA 36 | AH31: 950270639 | AI31: 950270639 | AK31: LA FLORIDA | AL31: 02/03/2000 | AM31: ALAN.MARTINEZ.ANTIL@GMAIL.COM | AO31: AUTOMOVIL | AP31: POLO | AQ31: BZ33D311 | AR31: GRIS PLATINO | AS31: 9BWAH5BZ8ST602190 | AT31: 9BWAH5BZ8ST602190 | AU31: NUEVO Y SIN USO | AV31: Facturada | AW31: 19853 | AX31: 13-01-2025 0:00:00 | AZ31: Guía de Despacho: 1 - Factura Electrónica: 1790936 | BA31: 14537722 | BB31: 13-01-2025 0:00:00 | BD31: 0 | BE31: AMIGO | BF31: 13-01-2025 0:00:00 | BG31: RETAIL | BH31: Peso | BJ31: 224 | BK31: 15957983 | BL31: -2923773 | BM31: 0 | BN31: 13034210 | BO31: 14537722 | BP31: -1503512 | BQ31: -11.54 % | BR31: 0 | BS31: 489290 | BT31: 489290 | BU31: 0 | BV31: 0 % | BW31: 0 | BX31: 0 | BY31: 0 | BZ31: 0 | CA31: 0 % | CB31: 0 | CC31: 0 | CD31: 0 | CE31: 0 | CF31: 0 % | CG31: 13034210 | CH31: 13523500 | CI31: 15027012 | CJ31: -1503512 | CK31: -11.12 % | CL31: -1503512 | CM31: -11.12 % | CN31: 0 | CO31: 0 | CP31: 16000000 | CQ31: 0 | CR31: 489290 | CS31: 0 | CT31: 16000000 | CU31: 13523500 | CV31: -1503512 | CW31: -11.12 % | CY31: 0 | DA31: 0 | DB31: 0 | DC31: 0
A32: ANDES MOTOR | B32: JETOUR | C32: T2 2.0T GDI AWD 7DCT LIMITED | D32: AN-25-01-0033 | E32: 2025 | F32: HJRPBGJB1SB203855 | G32: MATIAS AGLIATI GARRIDO | H32: Marcos Ignacio Campos Zavala | I32: N | J32: BK | K32: =BA32 -> 23185546 | L32: 175000 | M32: =BT32 -> 1460222 | P32: =CU32 -> 23717701 | Q32: 400000 | R32: =Q32/1.19 -> 336134.45 | S32: =T32*1.19 -> 0 | U32: 2000000 | V32: =U32/1.19 -> 1680672.3 | W32: =X32*1.19 -> 0 | Y32: =-K32-L32-M32-N32+O32+P32+R32+T32+V32+X32 -> 913739.72 | Z32: =VLOOKUP(D32,'Archivo con Bonos Ingresados '!V:CB,59,0) -> 913740 | AA32: =Z32-Y32 -> 0.27731092 | AB32: =Y32*100/CU32 -> 3.8525645 | AC32: 31-01-2025 10:48:39 | AD32: 5970 | AE32: 15959880 | AF32: 2 | AG32: LO CABAÑA 80 DPTO 804 | AH32: 93433346 | AI32: 993433346 | AK32: LAS CONDES | AL32: 27/11/1984 | AM32: MATIASAGLIATI@GMAIL.COM | AP32: T2 | AQ32: T2 2.0T GDI AWD 7DCT LIMITED | AR32: GRIS ARENA | AS32: HJRPBGJB1SB203855 | AT32: HJRPBGJB1SB203855 | AU32: NUEVO Y SIN USO | AV32: Parcial Facturada | AW32: 19958 | AX32: 31-01-2025 0:00:00 | AZ32: Guía de Despacho: 1 - Factura Electrónica: 206373 | BA32: 23185546 | BB32: 02-03-2025 0:00:00 | BD32: 0 | BE32: WEB CONCESIONARIO | BF32: 02-03-2025 0:00:00 | BG32: RETAIL | BH32: Peso | BI32: KZHK49 | BJ32: 9 | BK32: 25201681 | BL32: -2016807 | BM32: -927395 | BN32: 22257479 | BO32: 23185546 | BP32: -928067 | BQ32: -4.17 % | BR32: 0 | BS32: 1460222 | BT32: 1460222 | BU32: 0 | BV32: 0 % | BW32: 0 | BX32: 0 | BY32: 0 | BZ32: 0 | CA32: 0 % | CB32: 0 | CC32: 0 | CD32: 0 | CE32: 0 | CF32: 0 % | CG32: 23184874 | CH32: 23717701 | CI32: 24645768 | CJ32: -928067 | CK32: -3.91 % | CL32: -928067 | CM32: -3.91 % | CN32: 0 | CO32: 22500000 | CP32: 13268630 | CQ32: -7822008 | CR32: 1460222 | CS32: 0 | CT32: 27946622 | CU32: 23717701 | CV32: -928067 | CW32: -3.91 % | CY32: 0 | DA32: 0 | DB32: 0 | DC32: 0
